[2024-11-04T14:33:52.125+0000] {local_task_job_runner.py:123} INFO - ::group::Pre task execution logs
[2024-11-04T14:33:52.156+0000] {taskinstance.py:2612} INFO - Dependencies all met for dep_context=non-requeueable deps ti=<TaskInstance: yandex_task_dag.data_loading manual__2024-11-04T14:33:41.246660+00:00 [queued]>
[2024-11-04T14:33:52.170+0000] {taskinstance.py:2612} INFO - Dependencies all met for dep_context=requeueable deps ti=<TaskInstance: yandex_task_dag.data_loading manual__2024-11-04T14:33:41.246660+00:00 [queued]>
[2024-11-04T14:33:52.170+0000] {taskinstance.py:2865} INFO - Starting attempt 1 of 1
[2024-11-04T14:33:52.195+0000] {taskinstance.py:2888} INFO - Executing <Task(PostgresOperator): data_loading> on 2024-11-04 14:33:41.246660+00:00
[2024-11-04T14:33:52.205+0000] {warnings.py:112} WARNING - /home/***/.local/lib/python3.12/site-packages/***/task/task_runner/standard_task_runner.py:70: DeprecationWarning: This process (pid=1585) is multi-threaded, use of fork() may lead to deadlocks in the child.
  pid = os.fork()

[2024-11-04T14:33:52.209+0000] {standard_task_runner.py:72} INFO - Started process 1587 to run task
[2024-11-04T14:33:52.212+0000] {standard_task_runner.py:104} INFO - Running: ['***', 'tasks', 'run', 'yandex_task_dag', 'data_loading', 'manual__2024-11-04T14:33:41.246660+00:00', '--job-id', '31', '--raw', '--subdir', 'DAGS_FOLDER/dag.py', '--cfg-path', '/tmp/tmpp1jx8u0e']
[2024-11-04T14:33:52.214+0000] {standard_task_runner.py:105} INFO - Job 31: Subtask data_loading
[2024-11-04T14:33:52.313+0000] {task_command.py:467} INFO - Running <TaskInstance: yandex_task_dag.data_loading manual__2024-11-04T14:33:41.246660+00:00 [running]> on host 94d9180b5540
[2024-11-04T14:33:52.529+0000] {taskinstance.py:3131} INFO - Exporting env vars: AIRFLOW_CTX_DAG_OWNER='***' AIRFLOW_CTX_DAG_ID='yandex_task_dag' AIRFLOW_CTX_TASK_ID='data_loading' AIRFLOW_CTX_EXECUTION_DATE='2024-11-04T14:33:41.246660+00:00' AIRFLOW_CTX_TRY_NUMBER='1' AIRFLOW_CTX_DAG_RUN_ID='manual__2024-11-04T14:33:41.246660+00:00'
[2024-11-04T14:33:52.532+0000] {logging_mixin.py:190} INFO - Task instance is in running state
[2024-11-04T14:33:52.533+0000] {logging_mixin.py:190} INFO -  Previous state of the Task instance: queued
[2024-11-04T14:33:52.533+0000] {logging_mixin.py:190} INFO - Current task name:data_loading state:running start_date:2024-11-04 14:33:52.157053+00:00
[2024-11-04T14:33:52.534+0000] {logging_mixin.py:190} INFO - Dag name:yandex_task_dag and current dag run status:running
[2024-11-04T14:33:52.535+0000] {taskinstance.py:731} INFO - ::endgroup::
[2024-11-04T14:33:52.536+0000] {sql.py:266} INFO - Executing: COPY transactions FROM '/mnt/data_to_load/transactions.csv' DELIMITER ',' CSV HEADER;

COPY users FROM '/mnt/data_to_load/users.csv' DELIMITER ',' CSV HEADER;

COPY webinar FROM '/mnt/data_to_load/webinar.csv' DELIMITER ',' CSV HEADER;
[2024-11-04T14:33:52.553+0000] {base.py:84} INFO - Retrieving connection 'postgres'
[2024-11-04T14:33:52.577+0000] {base.py:84} INFO - Retrieving connection 'postgres'
[2024-11-04T14:33:52.596+0000] {sql.py:509} INFO - Running statement: COPY transactions FROM '/mnt/data_to_load/transactions.csv' DELIMITER ',' CSV HEADER;

COPY users FROM '/mnt/data_to_load/users.csv' DELIMITER ',' CSV HEADER;

COPY webinar FROM '/mnt/data_to_load/webinar.csv' DELIMITER ',' CSV HEADER;, parameters: None
[2024-11-04T14:33:52.617+0000] {taskinstance.py:3310} ERROR - Task failed with exception
Traceback (most recent call last):
  File "/home/airflow/.local/lib/python3.12/site-packages/airflow/models/taskinstance.py", line 767, in _execute_task
    result = _execute_callable(context=context, **execute_callable_kwargs)
             ^^^^^^^^^^^^^^^^^^^^^^^^^^^^^^^^^^^^^^^^^^^^^^^^^^^^^^^^^^^^^
  File "/home/airflow/.local/lib/python3.12/site-packages/airflow/models/taskinstance.py", line 733, in _execute_callable
    return ExecutionCallableRunner(
           ^^^^^^^^^^^^^^^^^^^^^^^^
  File "/home/airflow/.local/lib/python3.12/site-packages/airflow/utils/operator_helpers.py", line 252, in run
    return self.func(*args, **kwargs)
           ^^^^^^^^^^^^^^^^^^^^^^^^^^
  File "/home/airflow/.local/lib/python3.12/site-packages/airflow/models/baseoperator.py", line 406, in wrapper
    return func(self, *args, **kwargs)
           ^^^^^^^^^^^^^^^^^^^^^^^^^^^
  File "/home/airflow/.local/lib/python3.12/site-packages/airflow/providers/common/sql/operators/sql.py", line 272, in execute
    output = hook.run(
             ^^^^^^^^^
  File "/home/airflow/.local/lib/python3.12/site-packages/airflow/providers/common/sql/hooks/sql.py", line 456, in run
    self._run_command(cur, sql_statement, parameters)
  File "/home/airflow/.local/lib/python3.12/site-packages/airflow/providers/common/sql/hooks/sql.py", line 514, in _run_command
    cur.execute(sql_statement)
psycopg2.errors.UniqueViolation: duplicate key value violates unique constraint "users_pkey"
DETAIL:  Key (user_id)=(456451) already exists.
CONTEXT:  COPY users, line 2

[2024-11-04T14:33:52.642+0000] {logging_mixin.py:190} INFO - Task instance in failure state
[2024-11-04T14:33:52.643+0000] {logging_mixin.py:190} INFO - Task start:2024-11-04 14:33:52.157053+00:00 end:2024-11-04 14:33:52.641141+00:00 duration:0.484088
[2024-11-04T14:33:52.644+0000] {logging_mixin.py:190} INFO - Task:<Task(PostgresOperator): data_loading> dag:<DAG: yandex_task_dag> dagrun:<DagRun yandex_task_dag @ 2024-11-04 14:33:41.246660+00:00: manual__2024-11-04T14:33:41.246660+00:00, state:running, queued_at: 2024-11-04 14:33:41.369038+00:00. externally triggered: True>
[2024-11-04T14:33:52.644+0000] {logging_mixin.py:190} INFO - Failure caused by duplicate key value violates unique constraint "users_pkey"
DETAIL:  Key (user_id)=(456451) already exists.
CONTEXT:  COPY users, line 2
[2024-11-04T14:33:52.645+0000] {taskinstance.py:1225} INFO - Marking task as FAILED. dag_id=yandex_task_dag, task_id=data_loading, run_id=manual__2024-11-04T14:33:41.246660+00:00, execution_date=20241104T143341, start_date=20241104T143352, end_date=20241104T143352
[2024-11-04T14:33:52.666+0000] {taskinstance.py:340} INFO - ::group::Post task execution logs
[2024-11-04T14:33:52.667+0000] {standard_task_runner.py:124} ERROR - Failed to execute job 31 for task data_loading (duplicate key value violates unique constraint "users_pkey"
DETAIL:  Key (user_id)=(456451) already exists.
CONTEXT:  COPY users, line 2
; 1587)
Traceback (most recent call last):
  File "/home/airflow/.local/lib/python3.12/site-packages/airflow/task/task_runner/standard_task_runner.py", line 117, in _start_by_fork
    ret = args.func(args, dag=self.dag)
          ^^^^^^^^^^^^^^^^^^^^^^^^^^^^^
  File "/home/airflow/.local/lib/python3.12/site-packages/airflow/cli/cli_config.py", line 49, in command
    return func(*args, **kwargs)
           ^^^^^^^^^^^^^^^^^^^^^
  File "/home/airflow/.local/lib/python3.12/site-packages/airflow/utils/cli.py", line 115, in wrapper
    return f(*args, **kwargs)
           ^^^^^^^^^^^^^^^^^^
  File "/home/airflow/.local/lib/python3.12/site-packages/airflow/cli/commands/task_command.py", line 483, in task_run
    task_return_code = _run_task_by_selected_method(args, _dag, ti)
                       ^^^^^^^^^^^^^^^^^^^^^^^^^^^^^^^^^^^^^^^^^^^^
  File "/home/airflow/.local/lib/python3.12/site-packages/airflow/cli/commands/task_command.py", line 256, in _run_task_by_selected_method
    return _run_raw_task(args, ti)
           ^^^^^^^^^^^^^^^^^^^^^^^
  File "/home/airflow/.local/lib/python3.12/site-packages/airflow/cli/commands/task_command.py", line 341, in _run_raw_task
    return ti._run_raw_task(
           ^^^^^^^^^^^^^^^^^
  File "/home/airflow/.local/lib/python3.12/site-packages/airflow/utils/session.py", line 97, in wrapper
    return func(*args, session=session, **kwargs)
           ^^^^^^^^^^^^^^^^^^^^^^^^^^^^^^^^^^^^^^
  File "/home/airflow/.local/lib/python3.12/site-packages/airflow/models/taskinstance.py", line 3004, in _run_raw_task
    return _run_raw_task(
           ^^^^^^^^^^^^^^
  File "/home/airflow/.local/lib/python3.12/site-packages/airflow/models/taskinstance.py", line 273, in _run_raw_task
    TaskInstance._execute_task_with_callbacks(
  File "/home/airflow/.local/lib/python3.12/site-packages/airflow/models/taskinstance.py", line 3158, in _execute_task_with_callbacks
    result = self._execute_task(context, task_orig)
             ^^^^^^^^^^^^^^^^^^^^^^^^^^^^^^^^^^^^^^
  File "/home/airflow/.local/lib/python3.12/site-packages/airflow/models/taskinstance.py", line 3182, in _execute_task
    return _execute_task(self, context, task_orig)
           ^^^^^^^^^^^^^^^^^^^^^^^^^^^^^^^^^^^^^^^
  File "/home/airflow/.local/lib/python3.12/site-packages/airflow/models/taskinstance.py", line 767, in _execute_task
    result = _execute_callable(context=context, **execute_callable_kwargs)
             ^^^^^^^^^^^^^^^^^^^^^^^^^^^^^^^^^^^^^^^^^^^^^^^^^^^^^^^^^^^^^
  File "/home/airflow/.local/lib/python3.12/site-packages/airflow/models/taskinstance.py", line 733, in _execute_callable
    return ExecutionCallableRunner(
           ^^^^^^^^^^^^^^^^^^^^^^^^
  File "/home/airflow/.local/lib/python3.12/site-packages/airflow/utils/operator_helpers.py", line 252, in run
    return self.func(*args, **kwargs)
           ^^^^^^^^^^^^^^^^^^^^^^^^^^
  File "/home/airflow/.local/lib/python3.12/site-packages/airflow/models/baseoperator.py", line 406, in wrapper
    return func(self, *args, **kwargs)
           ^^^^^^^^^^^^^^^^^^^^^^^^^^^
  File "/home/airflow/.local/lib/python3.12/site-packages/airflow/providers/common/sql/operators/sql.py", line 272, in execute
    output = hook.run(
             ^^^^^^^^^
  File "/home/airflow/.local/lib/python3.12/site-packages/airflow/providers/common/sql/hooks/sql.py", line 456, in run
    self._run_command(cur, sql_statement, parameters)
  File "/home/airflow/.local/lib/python3.12/site-packages/airflow/providers/common/sql/hooks/sql.py", line 514, in _run_command
    cur.execute(sql_statement)
psycopg2.errors.UniqueViolation: duplicate key value violates unique constraint "users_pkey"
DETAIL:  Key (user_id)=(456451) already exists.
CONTEXT:  COPY users, line 2

[2024-11-04T14:33:52.710+0000] {local_task_job_runner.py:266} INFO - Task exited with return code 1
[2024-11-04T14:33:52.722+0000] {warnings.py:112} WARNING - /home/***/.local/lib/python3.12/site-packages/***/models/baseoperator.py:1378: AirflowProviderDeprecationWarning: Call to deprecated class PostgresOperator. (Please use `***.providers.common.sql.operators.sql.SQLExecuteQueryOperator`.Also, you can provide `hook_params={'schema': <database>}`.)
  result = cls.__new__(cls)

[2024-11-04T14:33:52.748+0000] {taskinstance.py:3900} INFO - 0 downstream tasks scheduled from follow-on schedule check
[2024-11-04T14:33:52.757+0000] {local_task_job_runner.py:245} INFO - ::endgroup::
