[2024-11-04T14:39:14.452+0000] {local_task_job_runner.py:123} INFO - ::group::Pre task execution logs
[2024-11-04T14:39:14.474+0000] {taskinstance.py:2612} INFO - Dependencies all met for dep_context=non-requeueable deps ti=<TaskInstance: yandex_task_dag.view_creation manual__2024-11-04T14:33:41.246660+00:00 [queued]>
[2024-11-04T14:39:14.488+0000] {taskinstance.py:2612} INFO - Dependencies all met for dep_context=requeueable deps ti=<TaskInstance: yandex_task_dag.view_creation manual__2024-11-04T14:33:41.246660+00:00 [queued]>
[2024-11-04T14:39:14.489+0000] {taskinstance.py:2865} INFO - Starting attempt 1 of 1
[2024-11-04T14:39:14.507+0000] {taskinstance.py:2888} INFO - Executing <Task(PostgresOperator): view_creation> on 2024-11-04 14:33:41.246660+00:00
[2024-11-04T14:39:14.518+0000] {warnings.py:112} WARNING - /home/***/.local/lib/python3.12/site-packages/***/task/task_runner/standard_task_runner.py:70: DeprecationWarning: This process (pid=1663) is multi-threaded, use of fork() may lead to deadlocks in the child.
  pid = os.fork()

[2024-11-04T14:39:14.521+0000] {standard_task_runner.py:72} INFO - Started process 1665 to run task
[2024-11-04T14:39:14.522+0000] {standard_task_runner.py:104} INFO - Running: ['***', 'tasks', 'run', 'yandex_task_dag', 'view_creation', 'manual__2024-11-04T14:33:41.246660+00:00', '--job-id', '35', '--raw', '--subdir', 'DAGS_FOLDER/dag.py', '--cfg-path', '/tmp/tmpv35dce53']
[2024-11-04T14:39:14.525+0000] {standard_task_runner.py:105} INFO - Job 35: Subtask view_creation
[2024-11-04T14:39:14.583+0000] {task_command.py:467} INFO - Running <TaskInstance: yandex_task_dag.view_creation manual__2024-11-04T14:33:41.246660+00:00 [running]> on host 94d9180b5540
[2024-11-04T14:39:14.698+0000] {taskinstance.py:3131} INFO - Exporting env vars: AIRFLOW_CTX_DAG_OWNER='***' AIRFLOW_CTX_DAG_ID='yandex_task_dag' AIRFLOW_CTX_TASK_ID='view_creation' AIRFLOW_CTX_EXECUTION_DATE='2024-11-04T14:33:41.246660+00:00' AIRFLOW_CTX_TRY_NUMBER='1' AIRFLOW_CTX_DAG_RUN_ID='manual__2024-11-04T14:33:41.246660+00:00'
[2024-11-04T14:39:14.699+0000] {logging_mixin.py:190} INFO - Task instance is in running state
[2024-11-04T14:39:14.700+0000] {logging_mixin.py:190} INFO -  Previous state of the Task instance: queued
[2024-11-04T14:39:14.701+0000] {logging_mixin.py:190} INFO - Current task name:view_creation state:running start_date:2024-11-04 14:39:14.475538+00:00
[2024-11-04T14:39:14.702+0000] {logging_mixin.py:190} INFO - Dag name:yandex_task_dag and current dag run status:running
[2024-11-04T14:39:14.703+0000] {taskinstance.py:731} INFO - ::endgroup::
[2024-11-04T14:39:14.704+0000] {sql.py:266} INFO - Executing: CREATE MATERIALIZED VIEW replenishments AS
WITH first_reg_users AS (
    SELECT * FROM (
        SELECT *, min(date_registration::DATE) OVER (PARTITION BY email) AS first_reg_date
        FROM users
    ) u
    WHERE first_reg_date > '2016-04-01'
)
SELECT w.email AS email, sum(price) AS price_sum
FROM first_reg_users f 
INNER JOIN webinar w ON f.email = w.email
INNER JOIN transactions t ON f.user_id = t.user_id
GROUP BY w.email;



[2024-11-04T14:39:14.715+0000] {base.py:84} INFO - Retrieving connection 'postgres'
[2024-11-04T14:39:14.728+0000] {base.py:84} INFO - Retrieving connection 'postgres'
[2024-11-04T14:39:14.744+0000] {sql.py:509} INFO - Running statement: CREATE MATERIALIZED VIEW replenishments AS
WITH first_reg_users AS (
    SELECT * FROM (
        SELECT *, min(date_registration::DATE) OVER (PARTITION BY email) AS first_reg_date
        FROM users
    ) u
    WHERE first_reg_date > '2016-04-01'
)
SELECT w.email AS email, sum(price) AS price_sum
FROM first_reg_users f 
INNER JOIN webinar w ON f.email = w.email
INNER JOIN transactions t ON f.user_id = t.user_id
GROUP BY w.email;


, parameters: None
[2024-11-04T14:39:14.757+0000] {taskinstance.py:3310} ERROR - Task failed with exception
Traceback (most recent call last):
  File "/home/airflow/.local/lib/python3.12/site-packages/airflow/models/taskinstance.py", line 767, in _execute_task
    result = _execute_callable(context=context, **execute_callable_kwargs)
             ^^^^^^^^^^^^^^^^^^^^^^^^^^^^^^^^^^^^^^^^^^^^^^^^^^^^^^^^^^^^^
  File "/home/airflow/.local/lib/python3.12/site-packages/airflow/models/taskinstance.py", line 733, in _execute_callable
    return ExecutionCallableRunner(
           ^^^^^^^^^^^^^^^^^^^^^^^^
  File "/home/airflow/.local/lib/python3.12/site-packages/airflow/utils/operator_helpers.py", line 252, in run
    return self.func(*args, **kwargs)
           ^^^^^^^^^^^^^^^^^^^^^^^^^^
  File "/home/airflow/.local/lib/python3.12/site-packages/airflow/models/baseoperator.py", line 406, in wrapper
    return func(self, *args, **kwargs)
           ^^^^^^^^^^^^^^^^^^^^^^^^^^^
  File "/home/airflow/.local/lib/python3.12/site-packages/airflow/providers/common/sql/operators/sql.py", line 272, in execute
    output = hook.run(
             ^^^^^^^^^
  File "/home/airflow/.local/lib/python3.12/site-packages/airflow/providers/common/sql/hooks/sql.py", line 456, in run
    self._run_command(cur, sql_statement, parameters)
  File "/home/airflow/.local/lib/python3.12/site-packages/airflow/providers/common/sql/hooks/sql.py", line 514, in _run_command
    cur.execute(sql_statement)
psycopg2.errors.DuplicateTable: relation "replenishments" already exists

[2024-11-04T14:39:14.776+0000] {logging_mixin.py:190} INFO - Task instance in failure state
[2024-11-04T14:39:14.777+0000] {logging_mixin.py:190} INFO - Task start:2024-11-04 14:39:14.475538+00:00 end:2024-11-04 14:39:14.776089+00:00 duration:0.300551
[2024-11-04T14:39:14.778+0000] {logging_mixin.py:190} INFO - Task:<Task(PostgresOperator): view_creation> dag:<DAG: yandex_task_dag> dagrun:<DagRun yandex_task_dag @ 2024-11-04 14:33:41.246660+00:00: manual__2024-11-04T14:33:41.246660+00:00, state:running, queued_at: 2024-11-04 14:39:05.549548+00:00. externally triggered: True>
[2024-11-04T14:39:14.779+0000] {logging_mixin.py:190} INFO - Failure caused by relation "replenishments" already exists
[2024-11-04T14:39:14.780+0000] {taskinstance.py:1225} INFO - Marking task as FAILED. dag_id=yandex_task_dag, task_id=view_creation, run_id=manual__2024-11-04T14:33:41.246660+00:00, execution_date=20241104T143341, start_date=20241104T143914, end_date=20241104T143914
[2024-11-04T14:39:14.801+0000] {taskinstance.py:340} INFO - ::group::Post task execution logs
[2024-11-04T14:39:14.802+0000] {standard_task_runner.py:124} ERROR - Failed to execute job 35 for task view_creation (relation "replenishments" already exists
; 1665)
Traceback (most recent call last):
  File "/home/airflow/.local/lib/python3.12/site-packages/airflow/task/task_runner/standard_task_runner.py", line 117, in _start_by_fork
    ret = args.func(args, dag=self.dag)
          ^^^^^^^^^^^^^^^^^^^^^^^^^^^^^
  File "/home/airflow/.local/lib/python3.12/site-packages/airflow/cli/cli_config.py", line 49, in command
    return func(*args, **kwargs)
           ^^^^^^^^^^^^^^^^^^^^^
  File "/home/airflow/.local/lib/python3.12/site-packages/airflow/utils/cli.py", line 115, in wrapper
    return f(*args, **kwargs)
           ^^^^^^^^^^^^^^^^^^
  File "/home/airflow/.local/lib/python3.12/site-packages/airflow/cli/commands/task_command.py", line 483, in task_run
    task_return_code = _run_task_by_selected_method(args, _dag, ti)
                       ^^^^^^^^^^^^^^^^^^^^^^^^^^^^^^^^^^^^^^^^^^^^
  File "/home/airflow/.local/lib/python3.12/site-packages/airflow/cli/commands/task_command.py", line 256, in _run_task_by_selected_method
    return _run_raw_task(args, ti)
           ^^^^^^^^^^^^^^^^^^^^^^^
  File "/home/airflow/.local/lib/python3.12/site-packages/airflow/cli/commands/task_command.py", line 341, in _run_raw_task
    return ti._run_raw_task(
           ^^^^^^^^^^^^^^^^^
  File "/home/airflow/.local/lib/python3.12/site-packages/airflow/utils/session.py", line 97, in wrapper
    return func(*args, session=session, **kwargs)
           ^^^^^^^^^^^^^^^^^^^^^^^^^^^^^^^^^^^^^^
  File "/home/airflow/.local/lib/python3.12/site-packages/airflow/models/taskinstance.py", line 3004, in _run_raw_task
    return _run_raw_task(
           ^^^^^^^^^^^^^^
  File "/home/airflow/.local/lib/python3.12/site-packages/airflow/models/taskinstance.py", line 273, in _run_raw_task
    TaskInstance._execute_task_with_callbacks(
  File "/home/airflow/.local/lib/python3.12/site-packages/airflow/models/taskinstance.py", line 3158, in _execute_task_with_callbacks
    result = self._execute_task(context, task_orig)
             ^^^^^^^^^^^^^^^^^^^^^^^^^^^^^^^^^^^^^^
  File "/home/airflow/.local/lib/python3.12/site-packages/airflow/models/taskinstance.py", line 3182, in _execute_task
    return _execute_task(self, context, task_orig)
           ^^^^^^^^^^^^^^^^^^^^^^^^^^^^^^^^^^^^^^^
  File "/home/airflow/.local/lib/python3.12/site-packages/airflow/models/taskinstance.py", line 767, in _execute_task
    result = _execute_callable(context=context, **execute_callable_kwargs)
             ^^^^^^^^^^^^^^^^^^^^^^^^^^^^^^^^^^^^^^^^^^^^^^^^^^^^^^^^^^^^^
  File "/home/airflow/.local/lib/python3.12/site-packages/airflow/models/taskinstance.py", line 733, in _execute_callable
    return ExecutionCallableRunner(
           ^^^^^^^^^^^^^^^^^^^^^^^^
  File "/home/airflow/.local/lib/python3.12/site-packages/airflow/utils/operator_helpers.py", line 252, in run
    return self.func(*args, **kwargs)
           ^^^^^^^^^^^^^^^^^^^^^^^^^^
  File "/home/airflow/.local/lib/python3.12/site-packages/airflow/models/baseoperator.py", line 406, in wrapper
    return func(self, *args, **kwargs)
           ^^^^^^^^^^^^^^^^^^^^^^^^^^^
  File "/home/airflow/.local/lib/python3.12/site-packages/airflow/providers/common/sql/operators/sql.py", line 272, in execute
    output = hook.run(
             ^^^^^^^^^
  File "/home/airflow/.local/lib/python3.12/site-packages/airflow/providers/common/sql/hooks/sql.py", line 456, in run
    self._run_command(cur, sql_statement, parameters)
  File "/home/airflow/.local/lib/python3.12/site-packages/airflow/providers/common/sql/hooks/sql.py", line 514, in _run_command
    cur.execute(sql_statement)
psycopg2.errors.DuplicateTable: relation "replenishments" already exists

[2024-11-04T14:39:14.818+0000] {local_task_job_runner.py:266} INFO - Task exited with return code 1
[2024-11-04T14:39:14.834+0000] {warnings.py:112} WARNING - /home/***/.local/lib/python3.12/site-packages/***/models/baseoperator.py:1378: AirflowProviderDeprecationWarning: Call to deprecated class PostgresOperator. (Please use `***.providers.common.sql.operators.sql.SQLExecuteQueryOperator`.Also, you can provide `hook_params={'schema': <database>}`.)
  result = cls.__new__(cls)

[2024-11-04T14:39:14.866+0000] {taskinstance.py:3900} INFO - 0 downstream tasks scheduled from follow-on schedule check
[2024-11-04T14:39:14.875+0000] {local_task_job_runner.py:245} INFO - ::endgroup::
