[2024-11-04T16:20:57.762+0000] {local_task_job_runner.py:123} INFO - ::group::Pre task execution logs
[2024-11-04T16:20:57.780+0000] {taskinstance.py:2612} INFO - Dependencies all met for dep_context=non-requeueable deps ti=<TaskInstance: yandex_task_dag.sending_to_clickhouse manual__2024-11-04T16:20:37.059441+00:00 [queued]>
[2024-11-04T16:20:57.791+0000] {taskinstance.py:2612} INFO - Dependencies all met for dep_context=requeueable deps ti=<TaskInstance: yandex_task_dag.sending_to_clickhouse manual__2024-11-04T16:20:37.059441+00:00 [queued]>
[2024-11-04T16:20:57.792+0000] {taskinstance.py:2865} INFO - Starting attempt 1 of 1
[2024-11-04T16:20:57.809+0000] {taskinstance.py:2888} INFO - Executing <Task(PythonOperator): sending_to_clickhouse> on 2024-11-04 16:20:37.059441+00:00
[2024-11-04T16:20:57.819+0000] {warnings.py:112} WARNING - /home/***/.local/lib/python3.12/site-packages/***/task/task_runner/standard_task_runner.py:70: DeprecationWarning: This process (pid=327) is multi-threaded, use of fork() may lead to deadlocks in the child.
  pid = os.fork()

[2024-11-04T16:20:57.823+0000] {standard_task_runner.py:72} INFO - Started process 329 to run task
[2024-11-04T16:20:57.823+0000] {standard_task_runner.py:104} INFO - Running: ['***', 'tasks', 'run', 'yandex_task_dag', 'sending_to_clickhouse', 'manual__2024-11-04T16:20:37.059441+00:00', '--job-id', '42', '--raw', '--subdir', 'DAGS_FOLDER/dag.py', '--cfg-path', '/tmp/tmpbgbmzzxg']
[2024-11-04T16:20:57.824+0000] {standard_task_runner.py:105} INFO - Job 42: Subtask sending_to_clickhouse
[2024-11-04T16:20:57.887+0000] {task_command.py:467} INFO - Running <TaskInstance: yandex_task_dag.sending_to_clickhouse manual__2024-11-04T16:20:37.059441+00:00 [running]> on host d759fd8a501c
[2024-11-04T16:20:57.995+0000] {taskinstance.py:3131} INFO - Exporting env vars: AIRFLOW_CTX_DAG_OWNER='***' AIRFLOW_CTX_DAG_ID='yandex_task_dag' AIRFLOW_CTX_TASK_ID='sending_to_clickhouse' AIRFLOW_CTX_EXECUTION_DATE='2024-11-04T16:20:37.059441+00:00' AIRFLOW_CTX_TRY_NUMBER='1' AIRFLOW_CTX_DAG_RUN_ID='manual__2024-11-04T16:20:37.059441+00:00'
[2024-11-04T16:20:57.996+0000] {logging_mixin.py:190} INFO - Task instance is in running state
[2024-11-04T16:20:57.997+0000] {logging_mixin.py:190} INFO -  Previous state of the Task instance: queued
[2024-11-04T16:20:57.998+0000] {logging_mixin.py:190} INFO - Current task name:sending_to_clickhouse state:running start_date:2024-11-04 16:20:57.781575+00:00
[2024-11-04T16:20:57.998+0000] {logging_mixin.py:190} INFO - Dag name:yandex_task_dag and current dag run status:running
[2024-11-04T16:20:57.999+0000] {taskinstance.py:731} INFO - ::endgroup::
[2024-11-04T16:20:58.007+0000] {connectionpool.py:870} WARNING - Retrying (Retry(total=0, connect=None, read=None, redirect=0, status=None)) after connection broken by 'NewConnectionError('<urllib3.connection.HTTPConnection object at 0x7fe051762c90>: Failed to establish a new connection: [Errno 111] Connection refused')': /?
[2024-11-04T16:20:58.008+0000] {httpclient.py:446} WARNING - Unexpected Http Driver Exception
[2024-11-04T16:20:58.009+0000] {taskinstance.py:3310} ERROR - Task failed with exception
Traceback (most recent call last):
  File "/home/airflow/.local/lib/python3.12/site-packages/urllib3/connection.py", line 196, in _new_conn
    sock = connection.create_connection(
           ^^^^^^^^^^^^^^^^^^^^^^^^^^^^^
  File "/home/airflow/.local/lib/python3.12/site-packages/urllib3/util/connection.py", line 85, in create_connection
    raise err
  File "/home/airflow/.local/lib/python3.12/site-packages/urllib3/util/connection.py", line 73, in create_connection
    sock.connect(sa)
ConnectionRefusedError: [Errno 111] Connection refused

The above exception was the direct cause of the following exception:

Traceback (most recent call last):
  File "/home/airflow/.local/lib/python3.12/site-packages/urllib3/connectionpool.py", line 789, in urlopen
    response = self._make_request(
               ^^^^^^^^^^^^^^^^^^^
  File "/home/airflow/.local/lib/python3.12/site-packages/urllib3/connectionpool.py", line 495, in _make_request
    conn.request(
  File "/home/airflow/.local/lib/python3.12/site-packages/urllib3/connection.py", line 398, in request
    self.endheaders()
  File "/usr/local/lib/python3.12/http/client.py", line 1331, in endheaders
    self._send_output(message_body, encode_chunked=encode_chunked)
  File "/usr/local/lib/python3.12/http/client.py", line 1091, in _send_output
    self.send(msg)
  File "/usr/local/lib/python3.12/http/client.py", line 1035, in send
    self.connect()
  File "/home/airflow/.local/lib/python3.12/site-packages/urllib3/connection.py", line 236, in connect
    self.sock = self._new_conn()
                ^^^^^^^^^^^^^^^^
  File "/home/airflow/.local/lib/python3.12/site-packages/urllib3/connection.py", line 211, in _new_conn
    raise NewConnectionError(
urllib3.exceptions.NewConnectionError: <urllib3.connection.HTTPConnection object at 0x7fe051762cf0>: Failed to establish a new connection: [Errno 111] Connection refused

The above exception was the direct cause of the following exception:

Traceback (most recent call last):
  File "/home/airflow/.local/lib/python3.12/site-packages/clickhouse_connect/driver/httpclient.py", line 436, in _raw_request
    response = self.http.request(method, url, **kwargs)
               ^^^^^^^^^^^^^^^^^^^^^^^^^^^^^^^^^^^^^^^^
  File "/home/airflow/.local/lib/python3.12/site-packages/urllib3/_request_methods.py", line 144, in request
    return self.request_encode_body(
           ^^^^^^^^^^^^^^^^^^^^^^^^^
  File "/home/airflow/.local/lib/python3.12/site-packages/urllib3/_request_methods.py", line 279, in request_encode_body
    return self.urlopen(method, url, **extra_kw)
           ^^^^^^^^^^^^^^^^^^^^^^^^^^^^^^^^^^^^^
  File "/home/airflow/.local/lib/python3.12/site-packages/urllib3/poolmanager.py", line 443, in urlopen
    response = conn.urlopen(method, u.request_uri, **kw)
               ^^^^^^^^^^^^^^^^^^^^^^^^^^^^^^^^^^^^^^^^^
  File "/home/airflow/.local/lib/python3.12/site-packages/urllib3/connectionpool.py", line 873, in urlopen
    return self.urlopen(
           ^^^^^^^^^^^^^
  File "/home/airflow/.local/lib/python3.12/site-packages/urllib3/connectionpool.py", line 843, in urlopen
    retries = retries.increment(
              ^^^^^^^^^^^^^^^^^^
  File "/home/airflow/.local/lib/python3.12/site-packages/urllib3/util/retry.py", line 519, in increment
    raise MaxRetryError(_pool, url, reason) from reason  # type: ignore[arg-type]
    ^^^^^^^^^^^^^^^^^^^^^^^^^^^^^^^^^^^^^^^^^^^^^^^^^^^
urllib3.exceptions.MaxRetryError: HTTPConnectionPool(host='localhost', port=8123): Max retries exceeded with url: /? (Caused by NewConnectionError('<urllib3.connection.HTTPConnection object at 0x7fe051762cf0>: Failed to establish a new connection: [Errno 111] Connection refused'))

The above exception was the direct cause of the following exception:

Traceback (most recent call last):
  File "/home/airflow/.local/lib/python3.12/site-packages/airflow/models/taskinstance.py", line 767, in _execute_task
    result = _execute_callable(context=context, **execute_callable_kwargs)
             ^^^^^^^^^^^^^^^^^^^^^^^^^^^^^^^^^^^^^^^^^^^^^^^^^^^^^^^^^^^^^
  File "/home/airflow/.local/lib/python3.12/site-packages/airflow/models/taskinstance.py", line 733, in _execute_callable
    return ExecutionCallableRunner(
           ^^^^^^^^^^^^^^^^^^^^^^^^
  File "/home/airflow/.local/lib/python3.12/site-packages/airflow/utils/operator_helpers.py", line 252, in run
    return self.func(*args, **kwargs)
           ^^^^^^^^^^^^^^^^^^^^^^^^^^
  File "/home/airflow/.local/lib/python3.12/site-packages/airflow/models/baseoperator.py", line 406, in wrapper
    return func(self, *args, **kwargs)
           ^^^^^^^^^^^^^^^^^^^^^^^^^^^
  File "/home/airflow/.local/lib/python3.12/site-packages/airflow/operators/python.py", line 238, in execute
    return_value = self.execute_callable()
                   ^^^^^^^^^^^^^^^^^^^^^^^
  File "/home/airflow/.local/lib/python3.12/site-packages/airflow/operators/python.py", line 256, in execute_callable
    return runner.run(*self.op_args, **self.op_kwargs)
           ^^^^^^^^^^^^^^^^^^^^^^^^^^^^^^^^^^^^^^^^^^^
  File "/home/airflow/.local/lib/python3.12/site-packages/airflow/utils/operator_helpers.py", line 252, in run
    return self.func(*args, **kwargs)
           ^^^^^^^^^^^^^^^^^^^^^^^^^^
  File "/opt/airflow/dags/dag.py", line 13, in send_data_to_ch
    client = clickhouse_connect.get_client(host='localhost', username='default', password='password')
             ^^^^^^^^^^^^^^^^^^^^^^^^^^^^^^^^^^^^^^^^^^^^^^^^^^^^^^^^^^^^^^^^^^^^^^^^^^^^^^^^^^^^^^^^
  File "/home/airflow/.local/lib/python3.12/site-packages/clickhouse_connect/driver/__init__.py", line 115, in create_client
    return HttpClient(interface, host, port, username, password, database, settings=settings, **kwargs)
           ^^^^^^^^^^^^^^^^^^^^^^^^^^^^^^^^^^^^^^^^^^^^^^^^^^^^^^^^^^^^^^^^^^^^^^^^^^^^^^^^^^^^^^^^^^^^
  File "/home/airflow/.local/lib/python3.12/site-packages/clickhouse_connect/driver/httpclient.py", line 156, in __init__
    super().__init__(database=database,
  File "/home/airflow/.local/lib/python3.12/site-packages/clickhouse_connect/driver/client.py", line 68, in __init__
    self._init_common_settings(apply_server_timezone)
  File "/home/airflow/.local/lib/python3.12/site-packages/clickhouse_connect/driver/client.py", line 73, in _init_common_settings
    tuple(self.command('SELECT version(), timezone()', use_database=False))
          ^^^^^^^^^^^^^^^^^^^^^^^^^^^^^^^^^^^^^^^^^^^^^^^^^^^^^^^^^^^^^^^^
  File "/home/airflow/.local/lib/python3.12/site-packages/clickhouse_connect/driver/httpclient.py", line 350, in command
    response = self._raw_request(payload, params, headers, method, fields=fields, server_wait=False)
               ^^^^^^^^^^^^^^^^^^^^^^^^^^^^^^^^^^^^^^^^^^^^^^^^^^^^^^^^^^^^^^^^^^^^^^^^^^^^^^^^^^^^^
  File "/home/airflow/.local/lib/python3.12/site-packages/clickhouse_connect/driver/httpclient.py", line 448, in _raw_request
    raise OperationalError(f'Error {ex} executing HTTP request attempt {attempts}{err_url}') from ex
clickhouse_connect.driver.exceptions.OperationalError: Error HTTPConnectionPool(host='localhost', port=8123): Max retries exceeded with url: /? (Caused by NewConnectionError('<urllib3.connection.HTTPConnection object at 0x7fe051762cf0>: Failed to establish a new connection: [Errno 111] Connection refused')) executing HTTP request attempt 1 (http://localhost:8123)
[2024-11-04T16:20:58.030+0000] {logging_mixin.py:190} INFO - Task instance in failure state
[2024-11-04T16:20:58.031+0000] {logging_mixin.py:190} INFO - Task start:2024-11-04 16:20:57.781575+00:00 end:2024-11-04 16:20:58.030195+00:00 duration:0.24862
[2024-11-04T16:20:58.032+0000] {logging_mixin.py:190} INFO - Task:<Task(PythonOperator): sending_to_clickhouse> dag:<DAG: yandex_task_dag> dagrun:<DagRun yandex_task_dag @ 2024-11-04 16:20:37.059441+00:00: manual__2024-11-04T16:20:37.059441+00:00, state:running, queued_at: 2024-11-04 16:20:37.092554+00:00. externally triggered: True>
[2024-11-04T16:20:58.033+0000] {logging_mixin.py:190} INFO - Failure caused by Error HTTPConnectionPool(host='localhost', port=8123): Max retries exceeded with url: /? (Caused by NewConnectionError('<urllib3.connection.HTTPConnection object at 0x7fe051762cf0>: Failed to establish a new connection: [Errno 111] Connection refused')) executing HTTP request attempt 1 (http://localhost:8123)
[2024-11-04T16:20:58.033+0000] {taskinstance.py:1225} INFO - Marking task as FAILED. dag_id=yandex_task_dag, task_id=sending_to_clickhouse, run_id=manual__2024-11-04T16:20:37.059441+00:00, execution_date=20241104T162037, start_date=20241104T162057, end_date=20241104T162058
[2024-11-04T16:20:58.047+0000] {taskinstance.py:340} INFO - ::group::Post task execution logs
[2024-11-04T16:20:58.048+0000] {standard_task_runner.py:124} ERROR - Failed to execute job 42 for task sending_to_clickhouse (Error HTTPConnectionPool(host='localhost', port=8123): Max retries exceeded with url: /? (Caused by NewConnectionError('<urllib3.connection.HTTPConnection object at 0x7fe051762cf0>: Failed to establish a new connection: [Errno 111] Connection refused')) executing HTTP request attempt 1 (http://localhost:8123); 329)
Traceback (most recent call last):
  File "/home/airflow/.local/lib/python3.12/site-packages/urllib3/connection.py", line 196, in _new_conn
    sock = connection.create_connection(
           ^^^^^^^^^^^^^^^^^^^^^^^^^^^^^
  File "/home/airflow/.local/lib/python3.12/site-packages/urllib3/util/connection.py", line 85, in create_connection
    raise err
  File "/home/airflow/.local/lib/python3.12/site-packages/urllib3/util/connection.py", line 73, in create_connection
    sock.connect(sa)
ConnectionRefusedError: [Errno 111] Connection refused

The above exception was the direct cause of the following exception:

Traceback (most recent call last):
  File "/home/airflow/.local/lib/python3.12/site-packages/urllib3/connectionpool.py", line 789, in urlopen
    response = self._make_request(
               ^^^^^^^^^^^^^^^^^^^
  File "/home/airflow/.local/lib/python3.12/site-packages/urllib3/connectionpool.py", line 495, in _make_request
    conn.request(
  File "/home/airflow/.local/lib/python3.12/site-packages/urllib3/connection.py", line 398, in request
    self.endheaders()
  File "/usr/local/lib/python3.12/http/client.py", line 1331, in endheaders
    self._send_output(message_body, encode_chunked=encode_chunked)
  File "/usr/local/lib/python3.12/http/client.py", line 1091, in _send_output
    self.send(msg)
  File "/usr/local/lib/python3.12/http/client.py", line 1035, in send
    self.connect()
  File "/home/airflow/.local/lib/python3.12/site-packages/urllib3/connection.py", line 236, in connect
    self.sock = self._new_conn()
                ^^^^^^^^^^^^^^^^
  File "/home/airflow/.local/lib/python3.12/site-packages/urllib3/connection.py", line 211, in _new_conn
    raise NewConnectionError(
urllib3.exceptions.NewConnectionError: <urllib3.connection.HTTPConnection object at 0x7fe051762cf0>: Failed to establish a new connection: [Errno 111] Connection refused

The above exception was the direct cause of the following exception:

Traceback (most recent call last):
  File "/home/airflow/.local/lib/python3.12/site-packages/clickhouse_connect/driver/httpclient.py", line 436, in _raw_request
    response = self.http.request(method, url, **kwargs)
               ^^^^^^^^^^^^^^^^^^^^^^^^^^^^^^^^^^^^^^^^
  File "/home/airflow/.local/lib/python3.12/site-packages/urllib3/_request_methods.py", line 144, in request
    return self.request_encode_body(
           ^^^^^^^^^^^^^^^^^^^^^^^^^
  File "/home/airflow/.local/lib/python3.12/site-packages/urllib3/_request_methods.py", line 279, in request_encode_body
    return self.urlopen(method, url, **extra_kw)
           ^^^^^^^^^^^^^^^^^^^^^^^^^^^^^^^^^^^^^
  File "/home/airflow/.local/lib/python3.12/site-packages/urllib3/poolmanager.py", line 443, in urlopen
    response = conn.urlopen(method, u.request_uri, **kw)
               ^^^^^^^^^^^^^^^^^^^^^^^^^^^^^^^^^^^^^^^^^
  File "/home/airflow/.local/lib/python3.12/site-packages/urllib3/connectionpool.py", line 873, in urlopen
    return self.urlopen(
           ^^^^^^^^^^^^^
  File "/home/airflow/.local/lib/python3.12/site-packages/urllib3/connectionpool.py", line 843, in urlopen
    retries = retries.increment(
              ^^^^^^^^^^^^^^^^^^
  File "/home/airflow/.local/lib/python3.12/site-packages/urllib3/util/retry.py", line 519, in increment
    raise MaxRetryError(_pool, url, reason) from reason  # type: ignore[arg-type]
    ^^^^^^^^^^^^^^^^^^^^^^^^^^^^^^^^^^^^^^^^^^^^^^^^^^^
urllib3.exceptions.MaxRetryError: HTTPConnectionPool(host='localhost', port=8123): Max retries exceeded with url: /? (Caused by NewConnectionError('<urllib3.connection.HTTPConnection object at 0x7fe051762cf0>: Failed to establish a new connection: [Errno 111] Connection refused'))

The above exception was the direct cause of the following exception:

Traceback (most recent call last):
  File "/home/airflow/.local/lib/python3.12/site-packages/airflow/task/task_runner/standard_task_runner.py", line 117, in _start_by_fork
    ret = args.func(args, dag=self.dag)
          ^^^^^^^^^^^^^^^^^^^^^^^^^^^^^
  File "/home/airflow/.local/lib/python3.12/site-packages/airflow/cli/cli_config.py", line 49, in command
    return func(*args, **kwargs)
           ^^^^^^^^^^^^^^^^^^^^^
  File "/home/airflow/.local/lib/python3.12/site-packages/airflow/utils/cli.py", line 115, in wrapper
    return f(*args, **kwargs)
           ^^^^^^^^^^^^^^^^^^
  File "/home/airflow/.local/lib/python3.12/site-packages/airflow/cli/commands/task_command.py", line 483, in task_run
    task_return_code = _run_task_by_selected_method(args, _dag, ti)
                       ^^^^^^^^^^^^^^^^^^^^^^^^^^^^^^^^^^^^^^^^^^^^
  File "/home/airflow/.local/lib/python3.12/site-packages/airflow/cli/commands/task_command.py", line 256, in _run_task_by_selected_method
    return _run_raw_task(args, ti)
           ^^^^^^^^^^^^^^^^^^^^^^^
  File "/home/airflow/.local/lib/python3.12/site-packages/airflow/cli/commands/task_command.py", line 341, in _run_raw_task
    return ti._run_raw_task(
           ^^^^^^^^^^^^^^^^^
  File "/home/airflow/.local/lib/python3.12/site-packages/airflow/utils/session.py", line 97, in wrapper
    return func(*args, session=session, **kwargs)
           ^^^^^^^^^^^^^^^^^^^^^^^^^^^^^^^^^^^^^^
  File "/home/airflow/.local/lib/python3.12/site-packages/airflow/models/taskinstance.py", line 3004, in _run_raw_task
    return _run_raw_task(
           ^^^^^^^^^^^^^^
  File "/home/airflow/.local/lib/python3.12/site-packages/airflow/models/taskinstance.py", line 273, in _run_raw_task
    TaskInstance._execute_task_with_callbacks(
  File "/home/airflow/.local/lib/python3.12/site-packages/airflow/models/taskinstance.py", line 3158, in _execute_task_with_callbacks
    result = self._execute_task(context, task_orig)
             ^^^^^^^^^^^^^^^^^^^^^^^^^^^^^^^^^^^^^^
  File "/home/airflow/.local/lib/python3.12/site-packages/airflow/models/taskinstance.py", line 3182, in _execute_task
    return _execute_task(self, context, task_orig)
           ^^^^^^^^^^^^^^^^^^^^^^^^^^^^^^^^^^^^^^^
  File "/home/airflow/.local/lib/python3.12/site-packages/airflow/models/taskinstance.py", line 767, in _execute_task
    result = _execute_callable(context=context, **execute_callable_kwargs)
             ^^^^^^^^^^^^^^^^^^^^^^^^^^^^^^^^^^^^^^^^^^^^^^^^^^^^^^^^^^^^^
  File "/home/airflow/.local/lib/python3.12/site-packages/airflow/models/taskinstance.py", line 733, in _execute_callable
    return ExecutionCallableRunner(
           ^^^^^^^^^^^^^^^^^^^^^^^^
  File "/home/airflow/.local/lib/python3.12/site-packages/airflow/utils/operator_helpers.py", line 252, in run
    return self.func(*args, **kwargs)
           ^^^^^^^^^^^^^^^^^^^^^^^^^^
  File "/home/airflow/.local/lib/python3.12/site-packages/airflow/models/baseoperator.py", line 406, in wrapper
    return func(self, *args, **kwargs)
           ^^^^^^^^^^^^^^^^^^^^^^^^^^^
  File "/home/airflow/.local/lib/python3.12/site-packages/airflow/operators/python.py", line 238, in execute
    return_value = self.execute_callable()
                   ^^^^^^^^^^^^^^^^^^^^^^^
  File "/home/airflow/.local/lib/python3.12/site-packages/airflow/operators/python.py", line 256, in execute_callable
    return runner.run(*self.op_args, **self.op_kwargs)
           ^^^^^^^^^^^^^^^^^^^^^^^^^^^^^^^^^^^^^^^^^^^
  File "/home/airflow/.local/lib/python3.12/site-packages/airflow/utils/operator_helpers.py", line 252, in run
    return self.func(*args, **kwargs)
           ^^^^^^^^^^^^^^^^^^^^^^^^^^
  File "/opt/airflow/dags/dag.py", line 13, in send_data_to_ch
    client = clickhouse_connect.get_client(host='localhost', username='default', password='password')
             ^^^^^^^^^^^^^^^^^^^^^^^^^^^^^^^^^^^^^^^^^^^^^^^^^^^^^^^^^^^^^^^^^^^^^^^^^^^^^^^^^^^^^^^^
  File "/home/airflow/.local/lib/python3.12/site-packages/clickhouse_connect/driver/__init__.py", line 115, in create_client
    return HttpClient(interface, host, port, username, password, database, settings=settings, **kwargs)
           ^^^^^^^^^^^^^^^^^^^^^^^^^^^^^^^^^^^^^^^^^^^^^^^^^^^^^^^^^^^^^^^^^^^^^^^^^^^^^^^^^^^^^^^^^^^^
  File "/home/airflow/.local/lib/python3.12/site-packages/clickhouse_connect/driver/httpclient.py", line 156, in __init__
    super().__init__(database=database,
  File "/home/airflow/.local/lib/python3.12/site-packages/clickhouse_connect/driver/client.py", line 68, in __init__
    self._init_common_settings(apply_server_timezone)
  File "/home/airflow/.local/lib/python3.12/site-packages/clickhouse_connect/driver/client.py", line 73, in _init_common_settings
    tuple(self.command('SELECT version(), timezone()', use_database=False))
          ^^^^^^^^^^^^^^^^^^^^^^^^^^^^^^^^^^^^^^^^^^^^^^^^^^^^^^^^^^^^^^^^
  File "/home/airflow/.local/lib/python3.12/site-packages/clickhouse_connect/driver/httpclient.py", line 350, in command
    response = self._raw_request(payload, params, headers, method, fields=fields, server_wait=False)
               ^^^^^^^^^^^^^^^^^^^^^^^^^^^^^^^^^^^^^^^^^^^^^^^^^^^^^^^^^^^^^^^^^^^^^^^^^^^^^^^^^^^^^
  File "/home/airflow/.local/lib/python3.12/site-packages/clickhouse_connect/driver/httpclient.py", line 448, in _raw_request
    raise OperationalError(f'Error {ex} executing HTTP request attempt {attempts}{err_url}') from ex
clickhouse_connect.driver.exceptions.OperationalError: Error HTTPConnectionPool(host='localhost', port=8123): Max retries exceeded with url: /? (Caused by NewConnectionError('<urllib3.connection.HTTPConnection object at 0x7fe051762cf0>: Failed to establish a new connection: [Errno 111] Connection refused')) executing HTTP request attempt 1 (http://localhost:8123)
[2024-11-04T16:20:58.078+0000] {local_task_job_runner.py:266} INFO - Task exited with return code 1
[2024-11-04T16:20:58.110+0000] {taskinstance.py:3900} INFO - 0 downstream tasks scheduled from follow-on schedule check
[2024-11-04T16:20:58.117+0000] {local_task_job_runner.py:245} INFO - ::endgroup::
