[2024-11-04T12:49:33.086+0000] {local_task_job_runner.py:123} INFO - ::group::Pre task execution logs
[2024-11-04T12:49:33.110+0000] {taskinstance.py:2612} INFO - Dependencies all met for dep_context=non-requeueable deps ti=<TaskInstance: yandex_task_dag.table_creation manual__2024-11-04T12:38:18.871536+00:00 [queued]>
[2024-11-04T12:49:33.125+0000] {taskinstance.py:2612} INFO - Dependencies all met for dep_context=requeueable deps ti=<TaskInstance: yandex_task_dag.table_creation manual__2024-11-04T12:38:18.871536+00:00 [queued]>
[2024-11-04T12:49:33.125+0000] {taskinstance.py:2865} INFO - Starting attempt 6 of 6
[2024-11-04T12:49:33.150+0000] {taskinstance.py:2888} INFO - Executing <Task(PostgresOperator): table_creation> on 2024-11-04 12:38:18.871536+00:00
[2024-11-04T12:49:33.162+0000] {warnings.py:112} WARNING - /home/***/.local/lib/python3.12/site-packages/***/task/task_runner/standard_task_runner.py:70: DeprecationWarning: This process (pid=245) is multi-threaded, use of fork() may lead to deadlocks in the child.
  pid = os.fork()

[2024-11-04T12:49:33.165+0000] {standard_task_runner.py:72} INFO - Started process 247 to run task
[2024-11-04T12:49:33.166+0000] {standard_task_runner.py:104} INFO - Running: ['***', 'tasks', 'run', 'yandex_task_dag', 'table_creation', 'manual__2024-11-04T12:38:18.871536+00:00', '--job-id', '24', '--raw', '--subdir', 'DAGS_FOLDER/dag.py', '--cfg-path', '/tmp/tmp0yhkxcmg']
[2024-11-04T12:49:33.168+0000] {standard_task_runner.py:105} INFO - Job 24: Subtask table_creation
[2024-11-04T12:49:33.235+0000] {task_command.py:467} INFO - Running <TaskInstance: yandex_task_dag.table_creation manual__2024-11-04T12:38:18.871536+00:00 [running]> on host 94d9180b5540
[2024-11-04T12:49:33.374+0000] {taskinstance.py:3131} INFO - Exporting env vars: AIRFLOW_CTX_DAG_OWNER='***' AIRFLOW_CTX_DAG_ID='yandex_task_dag' AIRFLOW_CTX_TASK_ID='table_creation' AIRFLOW_CTX_EXECUTION_DATE='2024-11-04T12:38:18.871536+00:00' AIRFLOW_CTX_TRY_NUMBER='6' AIRFLOW_CTX_DAG_RUN_ID='manual__2024-11-04T12:38:18.871536+00:00'
[2024-11-04T12:49:33.377+0000] {logging_mixin.py:190} INFO - Task instance is in running state
[2024-11-04T12:49:33.378+0000] {logging_mixin.py:190} INFO -  Previous state of the Task instance: queued
[2024-11-04T12:49:33.379+0000] {logging_mixin.py:190} INFO - Current task name:table_creation state:running start_date:2024-11-04 12:49:33.111567+00:00
[2024-11-04T12:49:33.379+0000] {logging_mixin.py:190} INFO - Dag name:yandex_task_dag and current dag run status:running
[2024-11-04T12:49:33.380+0000] {taskinstance.py:731} INFO - ::endgroup::
[2024-11-04T12:49:33.381+0000] {sql.py:266} INFO - Executing: CREATE TABLE IF NOT EXISTS transactions (
    user_id INT,
    price INT
);

CREATE TABLE IF NOT EXISTS users (
   user_id INT PRIMARY KEY,
   email VARCHAR,
   date_registration TIMESTAMP
);

CREATE TABLE IF NOT EXISTS webinar (
    email VARCHAR
);


COPY transactions FROM '/mnt/data_to_load/transactions.csv' DELIMITER ',' CSV HEADER;

COPY users FROM '/mnt/data_to_load/users.csv' DELIMITER ',' CSV HEADER;

COPY webinar FROM '/mnt/data_to_load/webinar.csv' DELIMITER ',' CSV HEADER;
[2024-11-04T12:49:33.393+0000] {base.py:84} INFO - Retrieving connection 'postgres'
[2024-11-04T12:49:33.407+0000] {base.py:84} INFO - Retrieving connection 'postgres'
[2024-11-04T12:49:33.409+0000] {taskinstance.py:3310} ERROR - Task failed with exception
Traceback (most recent call last):
  File "/home/airflow/.local/lib/python3.12/site-packages/airflow/models/taskinstance.py", line 767, in _execute_task
    result = _execute_callable(context=context, **execute_callable_kwargs)
             ^^^^^^^^^^^^^^^^^^^^^^^^^^^^^^^^^^^^^^^^^^^^^^^^^^^^^^^^^^^^^
  File "/home/airflow/.local/lib/python3.12/site-packages/airflow/models/taskinstance.py", line 733, in _execute_callable
    return ExecutionCallableRunner(
           ^^^^^^^^^^^^^^^^^^^^^^^^
  File "/home/airflow/.local/lib/python3.12/site-packages/airflow/utils/operator_helpers.py", line 252, in run
    return self.func(*args, **kwargs)
           ^^^^^^^^^^^^^^^^^^^^^^^^^^
  File "/home/airflow/.local/lib/python3.12/site-packages/airflow/models/baseoperator.py", line 406, in wrapper
    return func(self, *args, **kwargs)
           ^^^^^^^^^^^^^^^^^^^^^^^^^^^
  File "/home/airflow/.local/lib/python3.12/site-packages/airflow/providers/common/sql/operators/sql.py", line 272, in execute
    output = hook.run(
             ^^^^^^^^^
  File "/home/airflow/.local/lib/python3.12/site-packages/airflow/providers/common/sql/hooks/sql.py", line 452, in run
    with self._create_autocommit_connection(autocommit) as conn:
         ^^^^^^^^^^^^^^^^^^^^^^^^^^^^^^^^^^^^^^^^^^^^^^
  File "/usr/local/lib/python3.12/contextlib.py", line 137, in __enter__
    return next(self.gen)
           ^^^^^^^^^^^^^^
  File "/home/airflow/.local/lib/python3.12/site-packages/airflow/providers/common/sql/hooks/sql.py", line 574, in _create_autocommit_connection
    with closing(self.get_conn()) as conn:
                 ^^^^^^^^^^^^^^^
  File "/home/airflow/.local/lib/python3.12/site-packages/airflow/providers/postgres/hooks/postgres.py", line 176, in get_conn
    self.conn = psycopg2.connect(**conn_args)
                ^^^^^^^^^^^^^^^^^^^^^^^^^^^^^
  File "/home/airflow/.local/lib/python3.12/site-packages/psycopg2/__init__.py", line 122, in connect
    conn = _connect(dsn, connection_factory=connection_factory, **kwasync)
           ^^^^^^^^^^^^^^^^^^^^^^^^^^^^^^^^^^^^^^^^^^^^^^^^^^^^^^^^^^^^^^^
psycopg2.OperationalError: connection to server at "127.0.0.1", port 5432 failed: Connection refused
	Is the server running on that host and accepting TCP/IP connections?

[2024-11-04T12:49:33.423+0000] {logging_mixin.py:190} INFO - Task instance in failure state
[2024-11-04T12:49:33.424+0000] {logging_mixin.py:190} INFO - Task start:2024-11-04 12:49:33.111567+00:00 end:2024-11-04 12:49:33.423091+00:00 duration:0.311524
[2024-11-04T12:49:33.424+0000] {logging_mixin.py:190} INFO - Task:<Task(PostgresOperator): table_creation> dag:<DAG: yandex_task_dag> dagrun:<DagRun yandex_task_dag @ 2024-11-04 12:38:18.871536+00:00: manual__2024-11-04T12:38:18.871536+00:00, state:running, queued_at: 2024-11-04 12:49:30.718949+00:00. externally triggered: True>
[2024-11-04T12:49:33.425+0000] {logging_mixin.py:190} INFO - Failure caused by connection to server at "127.0.0.1", port 5432 failed: Connection refused
	Is the server running on that host and accepting TCP/IP connections?
[2024-11-04T12:49:33.425+0000] {taskinstance.py:1225} INFO - Marking task as FAILED. dag_id=yandex_task_dag, task_id=table_creation, run_id=manual__2024-11-04T12:38:18.871536+00:00, execution_date=20241104T123818, start_date=20241104T124933, end_date=20241104T124933
[2024-11-04T12:49:33.440+0000] {taskinstance.py:340} INFO - ::group::Post task execution logs
[2024-11-04T12:49:33.442+0000] {standard_task_runner.py:124} ERROR - Failed to execute job 24 for task table_creation (connection to server at "127.0.0.1", port 5432 failed: Connection refused
	Is the server running on that host and accepting TCP/IP connections?
; 247)
Traceback (most recent call last):
  File "/home/airflow/.local/lib/python3.12/site-packages/airflow/task/task_runner/standard_task_runner.py", line 117, in _start_by_fork
    ret = args.func(args, dag=self.dag)
          ^^^^^^^^^^^^^^^^^^^^^^^^^^^^^
  File "/home/airflow/.local/lib/python3.12/site-packages/airflow/cli/cli_config.py", line 49, in command
    return func(*args, **kwargs)
           ^^^^^^^^^^^^^^^^^^^^^
  File "/home/airflow/.local/lib/python3.12/site-packages/airflow/utils/cli.py", line 115, in wrapper
    return f(*args, **kwargs)
           ^^^^^^^^^^^^^^^^^^
  File "/home/airflow/.local/lib/python3.12/site-packages/airflow/cli/commands/task_command.py", line 483, in task_run
    task_return_code = _run_task_by_selected_method(args, _dag, ti)
                       ^^^^^^^^^^^^^^^^^^^^^^^^^^^^^^^^^^^^^^^^^^^^
  File "/home/airflow/.local/lib/python3.12/site-packages/airflow/cli/commands/task_command.py", line 256, in _run_task_by_selected_method
    return _run_raw_task(args, ti)
           ^^^^^^^^^^^^^^^^^^^^^^^
  File "/home/airflow/.local/lib/python3.12/site-packages/airflow/cli/commands/task_command.py", line 341, in _run_raw_task
    return ti._run_raw_task(
           ^^^^^^^^^^^^^^^^^
  File "/home/airflow/.local/lib/python3.12/site-packages/airflow/utils/session.py", line 97, in wrapper
    return func(*args, session=session, **kwargs)
           ^^^^^^^^^^^^^^^^^^^^^^^^^^^^^^^^^^^^^^
  File "/home/airflow/.local/lib/python3.12/site-packages/airflow/models/taskinstance.py", line 3004, in _run_raw_task
    return _run_raw_task(
           ^^^^^^^^^^^^^^
  File "/home/airflow/.local/lib/python3.12/site-packages/airflow/models/taskinstance.py", line 273, in _run_raw_task
    TaskInstance._execute_task_with_callbacks(
  File "/home/airflow/.local/lib/python3.12/site-packages/airflow/models/taskinstance.py", line 3158, in _execute_task_with_callbacks
    result = self._execute_task(context, task_orig)
             ^^^^^^^^^^^^^^^^^^^^^^^^^^^^^^^^^^^^^^
  File "/home/airflow/.local/lib/python3.12/site-packages/airflow/models/taskinstance.py", line 3182, in _execute_task
    return _execute_task(self, context, task_orig)
           ^^^^^^^^^^^^^^^^^^^^^^^^^^^^^^^^^^^^^^^
  File "/home/airflow/.local/lib/python3.12/site-packages/airflow/models/taskinstance.py", line 767, in _execute_task
    result = _execute_callable(context=context, **execute_callable_kwargs)
             ^^^^^^^^^^^^^^^^^^^^^^^^^^^^^^^^^^^^^^^^^^^^^^^^^^^^^^^^^^^^^
  File "/home/airflow/.local/lib/python3.12/site-packages/airflow/models/taskinstance.py", line 733, in _execute_callable
    return ExecutionCallableRunner(
           ^^^^^^^^^^^^^^^^^^^^^^^^
  File "/home/airflow/.local/lib/python3.12/site-packages/airflow/utils/operator_helpers.py", line 252, in run
    return self.func(*args, **kwargs)
           ^^^^^^^^^^^^^^^^^^^^^^^^^^
  File "/home/airflow/.local/lib/python3.12/site-packages/airflow/models/baseoperator.py", line 406, in wrapper
    return func(self, *args, **kwargs)
           ^^^^^^^^^^^^^^^^^^^^^^^^^^^
  File "/home/airflow/.local/lib/python3.12/site-packages/airflow/providers/common/sql/operators/sql.py", line 272, in execute
    output = hook.run(
             ^^^^^^^^^
  File "/home/airflow/.local/lib/python3.12/site-packages/airflow/providers/common/sql/hooks/sql.py", line 452, in run
    with self._create_autocommit_connection(autocommit) as conn:
         ^^^^^^^^^^^^^^^^^^^^^^^^^^^^^^^^^^^^^^^^^^^^^^
  File "/usr/local/lib/python3.12/contextlib.py", line 137, in __enter__
    return next(self.gen)
           ^^^^^^^^^^^^^^
  File "/home/airflow/.local/lib/python3.12/site-packages/airflow/providers/common/sql/hooks/sql.py", line 574, in _create_autocommit_connection
    with closing(self.get_conn()) as conn:
                 ^^^^^^^^^^^^^^^
  File "/home/airflow/.local/lib/python3.12/site-packages/airflow/providers/postgres/hooks/postgres.py", line 176, in get_conn
    self.conn = psycopg2.connect(**conn_args)
                ^^^^^^^^^^^^^^^^^^^^^^^^^^^^^
  File "/home/airflow/.local/lib/python3.12/site-packages/psycopg2/__init__.py", line 122, in connect
    conn = _connect(dsn, connection_factory=connection_factory, **kwasync)
           ^^^^^^^^^^^^^^^^^^^^^^^^^^^^^^^^^^^^^^^^^^^^^^^^^^^^^^^^^^^^^^^
psycopg2.OperationalError: connection to server at "127.0.0.1", port 5432 failed: Connection refused
	Is the server running on that host and accepting TCP/IP connections?

[2024-11-04T12:49:33.462+0000] {local_task_job_runner.py:266} INFO - Task exited with return code 1
[2024-11-04T12:49:33.477+0000] {warnings.py:112} WARNING - /home/***/.local/lib/python3.12/site-packages/***/models/baseoperator.py:1378: AirflowProviderDeprecationWarning: Call to deprecated class PostgresOperator. (Please use `***.providers.common.sql.operators.sql.SQLExecuteQueryOperator`.Also, you can provide `hook_params={'schema': <database>}`.)
  result = cls.__new__(cls)

[2024-11-04T12:49:33.506+0000] {taskinstance.py:3900} INFO - 0 downstream tasks scheduled from follow-on schedule check
[2024-11-04T12:49:33.511+0000] {local_task_job_runner.py:245} INFO - ::endgroup::
